<?xml version="1.0"?>
<robot name="differential_drive_robot">
  <!-- Base Link -->
  <link name="base_link">
    <inertial>
      <mass value="1.0"/>
      <origin xyz="0 0 0" rpy="0 0 0"/>
      <inertia ixx="1.0" ixy="0.0" ixz="0.0" iyy="1.0" iyz="0.0" izz="1.0"/>
    </inertial>
  </link>

  <!-- Left Wheel -->
  <link name="left_wheel"/>
  <joint name="left_wheel_joint" type="continuous">
    <parent link="base_link"/>
    <child link="left_wheel"/>
    <origin xyz="0.0 0.1 0" rpy="0 0 0"/>
    <axis xyz="0 1 0"/>
  </joint>

  <!-- Right Wheel -->
  <link name="right_wheel"/>
  <joint name="right_wheel_joint" type="continuous">
    <parent link="base_link"/>
    <child link="right_wheel"/>
    <origin xyz="0.0 -0.1 0" rpy="0 0 0"/>
    <axis xyz="0 1 0"/>
  </joint>
</robot>

<!-- Gazebo Plugin for Differential Drive -->
<gazebo>
  <plugin name="differential_drive_controller" filename="libgazebo_ros_diff_drive.so">
    <robotNamespace>/differential_drive_robot</robotNamespace>
    <commandTopic>cmd_vel</commandTopic>
    <odomTopic>odom</odomTopic>
    <leftWheelJoint>left_wheel_joint</leftWheelJoint>
    <rightWheelJoint>right_wheel_joint</rightWheelJoint>
    <wheelSeparation>0.2</wheelSeparation>
    <wheelDiameter>0.1</wheelDiameter>
  </plugin>
</gazebo>

